Workbook

Sheet Шаблон
A1: Объект | B1: Водитель | C1: Email водителя | D1: Плановая дата
A2: Вызревание | B2: ВодительНФ | D2: =VLOOKUP(A2,Лист1!$A$2:$E$2486,5,FALSE) -> 46266
A3: Косметолог | B3: ВодительНФ | D3: =VLOOKUP(A3,Лист1!$A$2:$E$2486,5,FALSE) -> 46266
A4: Мятый | B4: ВодительНФ | D4: =VLOOKUP(A4,Лист1!$A$2:$E$2486,5,FALSE) -> 46266
A5: Оберн | B5: ВодительНФ | D5: =VLOOKUP(A5,Лист1!$A$2:$E$2486,5,FALSE) -> 46266
A6: 50473 | B6: ВодительНФ | D6: =VLOOKUP(A6,Лист1!$A$2:$E$2486,5,FALSE) -> 46276
A7: 50856 | B7: ВодительНФ | D7: =VLOOKUP(A7,Лист1!$A$2:$E$2486,5,FALSE) -> 46276
A8: Глаголево | B8: ВодительНФ | D8: =VLOOKUP(A8,Лист1!$A$2:$E$2486,5,FALSE) -> 46266
A9: Жемчуг | B9: ВодительНФ | D9: =VLOOKUP(A9,Лист1!$A$2:$E$2486,5,FALSE) -> 46266
A10: Квеми | B10: ВодительНФ | D10: =VLOOKUP(A10,Лист1!$A$2:$E$2486,5,FALSE) -> 46266
A11: Квемо | B11: ВодительНФ | D11: =VLOOKUP(A11,Лист1!$A$2:$E$2486,5,FALSE) -> 46276
A12: Компьютерка | B12: ВодительНФ | D12: =VLOOKUP(A12,Лист1!$A$2:$E$2486,5,FALSE) -> 46266
A13: Наковка | B13: ВодительНФ | D13: =VLOOKUP(A13,Лист1!$A$2:$E$2486,5,FALSE) -> 46266
... A582: Интрузия | B582: Гончаров Артём | D582: =VLOOKUP(A582,Лист1!$A$2:$E$2486,5,FALSE) -> 46272
A583: 90463 | B583: Гончаров Артём
A584: 90653 | B584: Гончаров Артём
A585: 90664 | B585: Гончаров Артём
A586: Градусник | B586: Гончаров Артём
A587: Пелотас | B587: Гончаров Артём
A588: Андания | B588: Гришин Николай Сергеевич | D588: =VLOOKUP(A588,Лист1!$A$2:$E$2486,5,FALSE) -> 46266
A589: Гакрукс | B589: Гришин Николай Сергеевич | D589: =VLOOKUP(A589,Лист1!$A$2:$E$2486,5,FALSE) -> 46266
A590: Саночник | B590: Гришин Николай Сергеевич | D590: =VLOOKUP(A590,Лист1!$A$2:$E$2486,5,FALSE) -> 46266
A591: 77574 | B591: Гришин Николай Сергеевич | D591: =VLOOKUP(A591,Лист1!$A$2:$E$2486,5,FALSE) -> 46266
A592: Белгородская | B592: Гришин Николай Сергеевич | D592: =VLOOKUP(A592,Лист1!$A$2:$E$2486,5,FALSE) -> 46266
A593: Непобедимая | B593: Гришин Николай Сергеевич | D593: =VLOOKUP(A593,Лист1!$A$2:$E$2486,5,FALSE) -> 46266
A594: Поприще | B594: Гришин Николай Сергеевич | D594: =VLOOKUP(A594,Лист1!$A$2:$E$2486,5,FALSE) -> 46266
A595: Степурино | B595: Гришин Николай Сергеевич | D595: =VLOOKUP(A595,Лист1!$A$2:$E$2486,5,FALSE) -> 46266
A596: Терпенье | B596: Гришин Николай Сергеевич | D596: =VLOOKUP(A596,Лист1!$A$2:$E$2486,5,FALSE) -> 46266
A597: Головнин | B597: Гришин Николай Сергеевич | D597: =VLOOKUP(A597,Лист1!$A$2:$E$2486,5,FALSE) -> 46267
A598: Жакоби | B598: Гришин Николай Сергеевич | D598: =VLOOKUP(A598,Лист1!$A$2:$E$2486,5,FALSE) -> 46266
A599: Зернохранилище | B599: Гришин Николай Сергеевич | D599: =VLOOKUP(A599,Лист1!$A$2:$E$2486,5,FALSE) -> 46268
... A932: 33079 | B932: Гришин Николай Сергеевич | D932: =VLOOKUP(A932,Лист1!$A$2:$E$2486,5,FALSE) -> 46289
A933: 77975 | B933: Гришин Николай Сергеевич
A934: ММ приметив | B934: Гришин Николай Сергеевич
A935: 50804 | B935: Динаев Дмитрий Вадимович | D935: =VLOOKUP(A935,Лист1!$A$2:$E$2486,5,FALSE) -> 46266
A936: Секарево | B936: Динаев Дмитрий Вадимович | D936: =VLOOKUP(A936,Лист1!$A$2:$E$2486,5,FALSE) -> 46282
A937: Сухоблюдное | B937: Динаев Дмитрий Вадимович | D937: =VLOOKUP(A937,Лист1!$A$2:$E$2486,5,FALSE) -> 46282
A938: 77352 | B938: Динаев Дмитрий Вадимович | D938: =VLOOKUP(A938,Лист1!$A$2:$E$2486,5,FALSE) -> 46276
A939: 50642 | B939: Динаев Дмитрий Вадимович | D939: =VLOOKUP(A939,Лист1!$A$2:$E$2486,5,FALSE) -> 46276
A940: Мохлин | B940: Динаев Дмитрий Вадимович | D940: =VLOOKUP(A940,Лист1!$A$2:$E$2486,5,FALSE) -> 46282
...

Sheet Лист1
A1: объект
A2: 77800 | C2: Москва Север | D2: Москва, Кочновский проезд, д.4к1 | E2: 46273
A3: 50893 | B3: Бастион | C3: Звенигород, Клин, Краснознаменск | D3: 141601, Московская обл, Клинский р-н, Клин г, Ленинградская ул, д.52 | E3: 46293
A4: 90604 | B4: Бастион | C4: Звенигород, Клин, Краснознаменск | D4: МО, г.о.Клин, с.Петровское, ул.Лесхозная, д.5А | E4: 46293
A5: Лотрек | B5: Альт | C5: Щёлково | D5: МО, Щелково ул. Заповедная д.1Б | E5: 46266
A6: Мусинская | B6: Альт | C6: Щёлково | D6: 141143, МО, г. Щелково, д. Медвежьи Озера, стр.67Г | E6: 46266
A7: Напарье | B7: Альт | C7: Щёлково | D7: 141181, Московская обл, Щелковский р-н, Загорянский дп, Орджоникидзе ул, дом № Владение 46А, часть | E7: 46266
A8: Подрастание | B8: Альт | C8: Щёлково | D8: щелково 3 институтская стр.28 | E8: 46266
A9: Теруэль | B9: Альт | C9: Щёлково | D9: 141142, Московская обл, Щелковский р-н, Биокомбината п, дом № 6А | E9: 46266
A10: 90451 | B10: Бастион | C10: Щёлково | D10: МО, Щёлковский р-н, д.Большие Жеребцы, д.33в | E10: 46266
A11: 90618 | B11: Бастион | C11: Щёлково | D11: МО, г.о.Щелково, пгт.Загорянский, ул.Валентиновская, д.37к3 | E11: 46266
A12: 90662 | B12: Бастион | C12: Щёлково | D12: МО, г.Лосино-Петровский, площадь Революции, стр.21 | E12: 46266
A13: 50043 | B13: Визит | C13: Щёлково | D13: 141104, Московская обл, Щелковский р-н, Щелково 4 г, Беляева ул, д.41 А | E13: 46266
A14: 50804 | B14: Клининг МСК | C14: Домодедово | D14: Московская обл,Домодедово г,Центральный мкр,Каширское ш,д.91 | E14: 46266
... A435: 90028 | B435: Примекс | C435: Люберцы | D435: 140030, Московская обл, Люберецкий р-н, Малаховка п, Театральный проезд, д.16 | E435: 46280
A436: 90560 | C436: Ногинск | D436: МО, г.о.Богородский, д.Стромынь, мкр-н Ногинск-9, ул.Юбилейная, д.11А | E436: 46270
A437: 50075 | B437: Бастион | C437: Ногинск | D437: 142412, Московская обл, Ногинск , Климова ул, д.42, пом 1 | E437: 46270
A438: 90616 | B438: Бастион | C438: Ногинск | D438: МО г.Ногинск, ул.Клубная, д.3 | E438: 46270
A439: Аваренго | B439: МИКА | C439: Ногинск | D439: 142400, Московская обл, Ногинск г, Шибаевская ул, дом № 1 | E439: 46270
A440: Вопрос | B440: МИКА | C440: Ногинск | D440: 142451, Московская обл, Ногинск г, Рыбхоз п, Бисерово-парк мкр, дом № 1А | E440: 46270
A441: Додиннда | B441: МИКА | C441: Ногинск | D441: 142400, Московская обл, Ногинск г, Белякова ул, дом № 8, помещ 2 | E441: 46270
A442: Квенобани | B442: МИКА | C442: Ногинск | D442: 142412, Московская обл, Ногинск г, Климова ул, дом № 2 | E442: 46270
A443: Колывань | B443: МИКА | C443: Ногинск | D443: 142455, Москов-ская обл, Ногин-ский р-н, Элект-роугли г, Парко-вая ул, дом № 1 | E443: 46270
A444: Мутовчатая | B444: МИКА | C444: Ногинск | D444: 142436, Московская обл, Ногинск г, Боровково д, Серова ул, дом № 42, корпус А | E444: 46270
A445: Старовыжевский | B445: МИКА | C445: Ногинск | D445: 142400, Московская обл, Ногинск г, 1-ая Прудовая ул, дом № 1 | E445: 46270
A446: Хорлы | B446: МИКА | C446: Ногинск | D446: 142438, Московская обл, Ногинск г, Большое Буньково д, Ленинская ул, дом № 130 | E446: 46270
A447: Эйгер | B447: МИКА | C447: Ногинск | D447: 142402, Москов-ская обл, Но-гинск г, Чапаева ул, дом № 10, корпус А | E447: 46270
A448: 50089 | B448: Примекс | C448: Ногинск | D448: 142404, Московская обл, Ногинский р-н, Ногинск г, Советской Конституции ул, д.30 | E448: 46270
... A455: 50481 | B455: Примекс | C455: Ногинск | D455: 142450,Московская обл,Ногинский р-н,Старая Купавна г,Кирова ул,д.5 | E455: 46270
A456: 90556 | C456: Химки | D456: МО, Химки, мкр-н Подрезково, ул.Комсомольская, д.2 | E456: 46291
A457: Аптека Диетолог | B457: Альт | C457: Химки | D457: Московская обл, Химки г, Библиотечная ул, 6, пом. 001; Помещения : № 1-42 | E457: 46276
A458: Аптека Цзюлун | B458: Альт | C458: Химки | D458: Московская обл, Химки г, Юннатов ул, 10, строен. 2, пом. 003 | E458: 46276
A459: Градиско | B459: Альт | C459: Химки | D459: МО, Химки г., Елино д., д.22 | E459: 46276
A460: Дарума | B460: Альт | C460: Химки | D460: Химки г, Сходня мкр, Мичурина ул, дом № 17, корпус 5,6, кв.7 | E460: 46276
A461: Кандела | B461: Альт | C461: Химки | D461: Химки Сходня 1-йДачный переулок | E461: 46276
A462: Лалетино | B462: Альт | C462: Химки | D462: Химки г, Мельникова пр-кт, дом № 4, корпус а, кв.1 | E462: 46276
A463: Любимовский | B463: Альт | C463: Химки | D463: МО, Химки г., Германа Титова ул, д. 10А | E463: 46276
A464: Норилов | B464: Альт | C464: Химки | D464: Московская обл, Химки г, Новогорск мкр, улица Заречная, дом № строение 11/2, корпус 2 | E464: 46276
A465: Пестум | B465: Альт | C465: Химки | D465: 141407, МО, г. Химки пр-кт Юбилейный д. № 51, стр.1 | E465: 46276
A466: Риши | B466: Альт | C466: Химки | D466: Химки г, Маяковского ул, дом № 1, корпус А | E466: 46276
...

Sheet Справочник водителей
A1: Водитель | B1: Email
A2: ВодительНФ | B2: vod2@mail.com
A3: Гончаров Артём | B3: artem@mail.ru
A4: Гришин Николай Сергеевич | B4: gri2026@mail.com
A5: Динаев Дмитрий Вадимович | B5: dost2026@mail.com
A6: Жеглов Святослав Игоревич | B6: dostavka2026@mail.com
A7: Ковылин Александр | B7: aldost@mail.com
A8: Мазим Максим Александрович | B8: vodit@mail.com
A9: Питер | B9: piter@mail.ru
A10: ФИАТ ДУКАТО | B10: fiat@mail.com
A11: Чулкин Владислав Олегович | B11: vlad@mail.com
